[2024-01-13T20:51:35.850+0000] {taskinstance.py:1957} INFO - Dependencies all met for dep_context=non-requeueable deps ti=<TaskInstance: etl_dag.transform_data manual__2024-01-13T20:51:27.830345+00:00 [queued]>
[2024-01-13T20:51:35.885+0000] {taskinstance.py:1957} INFO - Dependencies all met for dep_context=requeueable deps ti=<TaskInstance: etl_dag.transform_data manual__2024-01-13T20:51:27.830345+00:00 [queued]>
[2024-01-13T20:51:35.886+0000] {taskinstance.py:2171} INFO - Starting attempt 1 of 2
[2024-01-13T20:51:36.032+0000] {taskinstance.py:2192} INFO - Executing <Task(PythonOperator): transform_data> on 2024-01-13 20:51:27.830345+00:00
[2024-01-13T20:51:36.074+0000] {standard_task_runner.py:60} INFO - Started process 4433 to run task
[2024-01-13T20:51:36.093+0000] {standard_task_runner.py:87} INFO - Running: ['***', 'tasks', 'run', 'etl_dag', 'transform_data', 'manual__2024-01-13T20:51:27.830345+00:00', '--job-id', '12', '--raw', '--subdir', 'DAGS_FOLDER/myfirstday.py', '--cfg-path', '/tmp/tmpp2tf_356']
[2024-01-13T20:51:36.097+0000] {standard_task_runner.py:88} INFO - Job 12: Subtask transform_data
[2024-01-13T20:51:36.294+0000] {task_command.py:423} INFO - Running <TaskInstance: etl_dag.transform_data manual__2024-01-13T20:51:27.830345+00:00 [running]> on host 004774b68eca
[2024-01-13T20:51:36.496+0000] {taskinstance.py:2481} INFO - Exporting env vars: AIRFLOW_CTX_DAG_OWNER='navanish' AIRFLOW_CTX_DAG_ID='etl_dag' AIRFLOW_CTX_TASK_ID='transform_data' AIRFLOW_CTX_EXECUTION_DATE='2024-01-13T20:51:27.830345+00:00' AIRFLOW_CTX_TRY_NUMBER='1' AIRFLOW_CTX_DAG_RUN_ID='manual__2024-01-13T20:51:27.830345+00:00'
[2024-01-13T20:51:36.503+0000] {taskinstance.py:2699} ERROR - Task failed with exception
Traceback (most recent call last):
  File "/home/airflow/.local/lib/python3.8/site-packages/airflow/models/taskinstance.py", line 433, in _execute_task
    result = execute_callable(context=context, **execute_callable_kwargs)
  File "/home/airflow/.local/lib/python3.8/site-packages/airflow/operators/python.py", line 199, in execute
    return_value = self.execute_callable()
  File "/home/airflow/.local/lib/python3.8/site-packages/airflow/operators/python.py", line 216, in execute_callable
    return self.python_callable(*self.op_args, **self.op_kwargs)
TypeError: transform_data() missing 1 required positional argument: 'html_text'
[2024-01-13T20:51:36.521+0000] {taskinstance.py:1138} INFO - Marking task as UP_FOR_RETRY. dag_id=etl_dag, task_id=transform_data, execution_date=20240113T205127, start_date=20240113T205135, end_date=20240113T205136
[2024-01-13T20:51:36.567+0000] {standard_task_runner.py:107} ERROR - Failed to execute job 12 for task transform_data (transform_data() missing 1 required positional argument: 'html_text'; 4433)
[2024-01-13T20:51:36.625+0000] {local_task_job_runner.py:234} INFO - Task exited with return code 1
[2024-01-13T20:51:36.681+0000] {taskinstance.py:3281} INFO - 0 downstream tasks scheduled from follow-on schedule check
