[2024-01-13T20:56:44.956+0000] {taskinstance.py:1957} INFO - Dependencies all met for dep_context=non-requeueable deps ti=<TaskInstance: etl_dag.load_data manual__2024-01-13T20:51:27.830345+00:00 [queued]>
[2024-01-13T20:56:44.976+0000] {taskinstance.py:1957} INFO - Dependencies all met for dep_context=requeueable deps ti=<TaskInstance: etl_dag.load_data manual__2024-01-13T20:51:27.830345+00:00 [queued]>
[2024-01-13T20:56:44.977+0000] {taskinstance.py:2171} INFO - Starting attempt 1 of 2
[2024-01-13T20:56:45.039+0000] {taskinstance.py:2192} INFO - Executing <Task(PythonOperator): load_data> on 2024-01-13 20:51:27.830345+00:00
[2024-01-13T20:56:45.067+0000] {standard_task_runner.py:60} INFO - Started process 4511 to run task
[2024-01-13T20:56:45.073+0000] {standard_task_runner.py:87} INFO - Running: ['***', 'tasks', 'run', 'etl_dag', 'load_data', 'manual__2024-01-13T20:51:27.830345+00:00', '--job-id', '14', '--raw', '--subdir', 'DAGS_FOLDER/myfirstday.py', '--cfg-path', '/tmp/tmppyrfv1_d']
[2024-01-13T20:56:45.076+0000] {standard_task_runner.py:88} INFO - Job 14: Subtask load_data
[2024-01-13T20:56:45.250+0000] {task_command.py:423} INFO - Running <TaskInstance: etl_dag.load_data manual__2024-01-13T20:51:27.830345+00:00 [running]> on host 004774b68eca
[2024-01-13T20:56:45.704+0000] {taskinstance.py:2481} INFO - Exporting env vars: AIRFLOW_CTX_DAG_OWNER='navanish' AIRFLOW_CTX_DAG_ID='etl_dag' AIRFLOW_CTX_TASK_ID='load_data' AIRFLOW_CTX_EXECUTION_DATE='2024-01-13T20:51:27.830345+00:00' AIRFLOW_CTX_TRY_NUMBER='1' AIRFLOW_CTX_DAG_RUN_ID='manual__2024-01-13T20:51:27.830345+00:00'
[2024-01-13T20:56:45.710+0000] {taskinstance.py:2699} ERROR - Task failed with exception
Traceback (most recent call last):
  File "/home/airflow/.local/lib/python3.8/site-packages/airflow/models/taskinstance.py", line 433, in _execute_task
    result = execute_callable(context=context, **execute_callable_kwargs)
  File "/home/airflow/.local/lib/python3.8/site-packages/airflow/operators/python.py", line 199, in execute
    return_value = self.execute_callable()
  File "/home/airflow/.local/lib/python3.8/site-packages/airflow/operators/python.py", line 216, in execute_callable
    return self.python_callable(*self.op_args, **self.op_kwargs)
TypeError: load_data() missing 1 required positional argument: 'final'
[2024-01-13T20:56:45.729+0000] {taskinstance.py:1138} INFO - Marking task as UP_FOR_RETRY. dag_id=etl_dag, task_id=load_data, execution_date=20240113T205127, start_date=20240113T205644, end_date=20240113T205645
[2024-01-13T20:56:45.826+0000] {standard_task_runner.py:107} ERROR - Failed to execute job 14 for task load_data (load_data() missing 1 required positional argument: 'final'; 4511)
[2024-01-13T20:56:45.849+0000] {local_task_job_runner.py:234} INFO - Task exited with return code 1
[2024-01-13T20:56:45.885+0000] {taskinstance.py:3281} INFO - 0 downstream tasks scheduled from follow-on schedule check
