[2024-01-13T21:05:51.746+0000] {taskinstance.py:1957} INFO - Dependencies all met for dep_context=non-requeueable deps ti=<TaskInstance: etl_dag.load_data manual__2024-01-13T21:05:37.155038+00:00 [queued]>
[2024-01-13T21:05:51.782+0000] {taskinstance.py:1957} INFO - Dependencies all met for dep_context=requeueable deps ti=<TaskInstance: etl_dag.load_data manual__2024-01-13T21:05:37.155038+00:00 [queued]>
[2024-01-13T21:05:51.784+0000] {taskinstance.py:2171} INFO - Starting attempt 1 of 2
[2024-01-13T21:05:51.861+0000] {taskinstance.py:2192} INFO - Executing <Task(PythonOperator): load_data> on 2024-01-13 21:05:37.155038+00:00
[2024-01-13T21:05:51.874+0000] {standard_task_runner.py:60} INFO - Started process 4683 to run task
[2024-01-13T21:05:51.880+0000] {standard_task_runner.py:87} INFO - Running: ['***', 'tasks', 'run', 'etl_dag', 'load_data', 'manual__2024-01-13T21:05:37.155038+00:00', '--job-id', '29', '--raw', '--subdir', 'DAGS_FOLDER/myfirstday.py', '--cfg-path', '/tmp/tmppgbrijhr']
[2024-01-13T21:05:51.883+0000] {standard_task_runner.py:88} INFO - Job 29: Subtask load_data
[2024-01-13T21:05:52.082+0000] {task_command.py:423} INFO - Running <TaskInstance: etl_dag.load_data manual__2024-01-13T21:05:37.155038+00:00 [running]> on host 004774b68eca
[2024-01-13T21:05:52.283+0000] {taskinstance.py:2481} INFO - Exporting env vars: AIRFLOW_CTX_DAG_OWNER='navanish' AIRFLOW_CTX_DAG_ID='etl_dag' AIRFLOW_CTX_TASK_ID='load_data' AIRFLOW_CTX_EXECUTION_DATE='2024-01-13T21:05:37.155038+00:00' AIRFLOW_CTX_TRY_NUMBER='1' AIRFLOW_CTX_DAG_RUN_ID='manual__2024-01-13T21:05:37.155038+00:00'
[2024-01-13T21:05:52.307+0000] {taskinstance.py:2699} ERROR - Task failed with exception
Traceback (most recent call last):
  File "/home/airflow/.local/lib/python3.8/site-packages/airflow/models/taskinstance.py", line 433, in _execute_task
    result = execute_callable(context=context, **execute_callable_kwargs)
  File "/home/airflow/.local/lib/python3.8/site-packages/airflow/operators/python.py", line 199, in execute
    return_value = self.execute_callable()
  File "/home/airflow/.local/lib/python3.8/site-packages/airflow/operators/python.py", line 216, in execute_callable
    return self.python_callable(*self.op_args, **self.op_kwargs)
  File "/opt/airflow/dags/myfirstday.py", line 48, in load_data
    final = ast.literal_eval(final)  # Convert string to dictionary
  File "/usr/local/lib/python3.8/ast.py", line 99, in literal_eval
    return _convert(node_or_string)
  File "/usr/local/lib/python3.8/ast.py", line 98, in _convert
    return _convert_signed_num(node)
  File "/usr/local/lib/python3.8/ast.py", line 75, in _convert_signed_num
    return _convert_num(node)
  File "/usr/local/lib/python3.8/ast.py", line 66, in _convert_num
    _raise_malformed_node(node)
  File "/usr/local/lib/python3.8/ast.py", line 63, in _raise_malformed_node
    raise ValueError(f'malformed node or string: {node!r}')
ValueError: malformed node or string: {'Market Cap': '5,65,463', 'Current Price': '634', 'High / Low': '660', 'Stock P/E': '9.10', 'Book Value': '367', 'Dividend Yield': '1.78', 'ROCE': '5.09', 'ROE': '16.5', 'Face Value': '1.00'}
[2024-01-13T21:05:52.345+0000] {taskinstance.py:1138} INFO - Marking task as UP_FOR_RETRY. dag_id=etl_dag, task_id=load_data, execution_date=20240113T210537, start_date=20240113T210551, end_date=20240113T210552
[2024-01-13T21:05:52.418+0000] {standard_task_runner.py:107} ERROR - Failed to execute job 29 for task load_data (malformed node or string: {'Market Cap': '5,65,463', 'Current Price': '634', 'High / Low': '660', 'Stock P/E': '9.10', 'Book Value': '367', 'Dividend Yield': '1.78', 'ROCE': '5.09', 'ROE': '16.5', 'Face Value': '1.00'}; 4683)
[2024-01-13T21:05:52.455+0000] {local_task_job_runner.py:234} INFO - Task exited with return code 1
[2024-01-13T21:05:52.487+0000] {taskinstance.py:3281} INFO - 0 downstream tasks scheduled from follow-on schedule check
