[2024-01-13T21:00:26.882+0000] {taskinstance.py:1957} INFO - Dependencies all met for dep_context=non-requeueable deps ti=<TaskInstance: etl_dag.load_data manual__2024-01-13T21:00:14.033363+00:00 [queued]>
[2024-01-13T21:00:26.900+0000] {taskinstance.py:1957} INFO - Dependencies all met for dep_context=requeueable deps ti=<TaskInstance: etl_dag.load_data manual__2024-01-13T21:00:14.033363+00:00 [queued]>
[2024-01-13T21:00:26.901+0000] {taskinstance.py:2171} INFO - Starting attempt 1 of 2
[2024-01-13T21:00:26.948+0000] {taskinstance.py:2192} INFO - Executing <Task(PythonOperator): load_data> on 2024-01-13 21:00:14.033363+00:00
[2024-01-13T21:00:26.957+0000] {standard_task_runner.py:60} INFO - Started process 4577 to run task
[2024-01-13T21:00:26.962+0000] {standard_task_runner.py:87} INFO - Running: ['***', 'tasks', 'run', 'etl_dag', 'load_data', 'manual__2024-01-13T21:00:14.033363+00:00', '--job-id', '20', '--raw', '--subdir', 'DAGS_FOLDER/myfirstday.py', '--cfg-path', '/tmp/tmpgdizuyoq']
[2024-01-13T21:00:26.965+0000] {standard_task_runner.py:88} INFO - Job 20: Subtask load_data
[2024-01-13T21:00:27.160+0000] {task_command.py:423} INFO - Running <TaskInstance: etl_dag.load_data manual__2024-01-13T21:00:14.033363+00:00 [running]> on host 004774b68eca
[2024-01-13T21:00:27.411+0000] {taskinstance.py:2481} INFO - Exporting env vars: AIRFLOW_CTX_DAG_OWNER='navanish' AIRFLOW_CTX_DAG_ID='etl_dag' AIRFLOW_CTX_TASK_ID='load_data' AIRFLOW_CTX_EXECUTION_DATE='2024-01-13T21:00:14.033363+00:00' AIRFLOW_CTX_TRY_NUMBER='1' AIRFLOW_CTX_DAG_RUN_ID='manual__2024-01-13T21:00:14.033363+00:00'
[2024-01-13T21:00:27.420+0000] {taskinstance.py:2699} ERROR - Task failed with exception
Traceback (most recent call last):
  File "/home/airflow/.local/lib/python3.8/site-packages/airflow/models/taskinstance.py", line 433, in _execute_task
    result = execute_callable(context=context, **execute_callable_kwargs)
  File "/home/airflow/.local/lib/python3.8/site-packages/airflow/operators/python.py", line 199, in execute
    return_value = self.execute_callable()
  File "/home/airflow/.local/lib/python3.8/site-packages/airflow/operators/python.py", line 216, in execute_callable
    return self.python_callable(*self.op_args, **self.op_kwargs)
  File "/opt/airflow/dags/myfirstday.py", line 41, in load_data
    df = pd.DataFrame(list(final.items()), columns=['Attribute', 'Value'])
AttributeError: 'str' object has no attribute 'items'
[2024-01-13T21:00:27.450+0000] {taskinstance.py:1138} INFO - Marking task as UP_FOR_RETRY. dag_id=etl_dag, task_id=load_data, execution_date=20240113T210014, start_date=20240113T210026, end_date=20240113T210027
[2024-01-13T21:00:27.498+0000] {standard_task_runner.py:107} ERROR - Failed to execute job 20 for task load_data ('str' object has no attribute 'items'; 4577)
[2024-01-13T21:00:27.537+0000] {local_task_job_runner.py:234} INFO - Task exited with return code 1
[2024-01-13T21:00:27.567+0000] {taskinstance.py:3281} INFO - 0 downstream tasks scheduled from follow-on schedule check
